ERROR 2013-07-05 13:08:08,914 base 8331 140336579999488 Internal Server Error: /
Traceback (most recent call last):
  File "/home/imran/Code/splintera-web/venv/local/lib/python2.7/site-packages/django/core/handlers/base.py", line 109, in get_response
    response = middleware_method(request, callback, callback_args, callback_kwargs)
  File "/home/imran/Code/splintera-web/venv/local/lib/python2.7/site-packages/splintera_client/tracer.py", line 24, in process_view
    return trace(view_func)(request, *view_args, **view_kwargs)
  File "/home/imran/Code/splintera-web/venv/local/lib/python2.7/site-packages/splintera_client/tracer.py", line 180, in wrapper
    result = f(*arg, **kw)
  File "/home/imran/Code/splintera-web/splintera/views.py", line 12, in dashboard
    import urllib2
  File "/home/imran/Code/splintera-web/splintera/views.py", line 12, in dashboard
    import urllib2
  File "/home/imran/Code/splintera-web/venv/local/lib/python2.7/site-packages/splintera_client/tracer.py", line 232, in trace_lines
    parsed = ast.parse(line_of_code) # get any variables assigned on this line
  File "/usr/lib/python2.7/ast.py", line 37, in parse
    return compile(source, filename, mode, PyCF_ONLY_AST)
  File "<unknown>", line 1
    import urllib2
   ^
IndentationError: unexpected indent
WARNING 2013-07-05 13:08:09,314 base 8331 140336579999488 Not Found: /favicon.ico/
ERROR 2013-07-05 13:19:52,345 base 8569 140099473430272 Internal Server Error: /
Traceback (most recent call last):
  File "/home/imran/Code/splintera-web/venv/local/lib/python2.7/site-packages/django/core/handlers/base.py", line 109, in get_response
    response = middleware_method(request, callback, callback_args, callback_kwargs)
  File "/home/imran/Code/splintera-web/venv/local/lib/python2.7/site-packages/splintera_client/tracer.py", line 24, in process_view
    return trace(view_func)(request, *view_args, **view_kwargs)
  File "/home/imran/Code/splintera-web/venv/local/lib/python2.7/site-packages/splintera_client/tracer.py", line 180, in wrapper
    result = f(*arg, **kw)
  File "/home/imran/Code/splintera-web/splintera/views.py", line 12, in dashboard
    import urllib2
  File "/home/imran/Code/splintera-web/splintera/views.py", line 12, in dashboard
    import urllib2
  File "/home/imran/Code/splintera-web/venv/local/lib/python2.7/site-packages/splintera_client/tracer.py", line 233, in trace_lines
    parsed = ast.parse(line_of_code) # get any variables assigned on this line
  File "/usr/lib/python2.7/ast.py", line 37, in parse
    return compile(source, filename, mode, PyCF_ONLY_AST)
  File "<unknown>", line 1
    import urllib2
   ^
IndentationError: unexpected indent
WARNING 2013-07-05 13:19:52,727 base 8569 140099473430272 Not Found: /favicon.ico/
ERROR 2013-07-05 13:27:42,893 base 8697 139681798813440 Internal Server Error: /
Traceback (most recent call last):
  File "/home/imran/Code/splintera-web/venv/local/lib/python2.7/site-packages/django/core/handlers/base.py", line 109, in get_response
    response = middleware_method(request, callback, callback_args, callback_kwargs)
  File "/home/imran/Code/splintera-web/venv/local/lib/python2.7/site-packages/splintera_client/tracer.py", line 24, in process_view
    return trace(view_func)(request, *view_args, **view_kwargs)
  File "/home/imran/Code/splintera-web/venv/local/lib/python2.7/site-packages/splintera_client/tracer.py", line 180, in wrapper
    result = f(*arg, **kw)
  File "/home/imran/Code/splintera-web/splintera/views.py", line 26, in dashboard
    for id, file_name, function_name in cur.fetchall():
  File "/home/imran/Code/splintera-web/splintera/views.py", line 26, in dashboard
    for id, file_name, function_name in cur.fetchall():
  File "/home/imran/Code/splintera-web/venv/local/lib/python2.7/site-packages/splintera_client/tracer.py", line 232, in trace_lines
    parsed = ast.parse(line_of_code) # get any variables assigned on this line
  File "/usr/lib/python2.7/ast.py", line 37, in parse
    return compile(source, filename, mode, PyCF_ONLY_AST)
  File "<unknown>", line 1
    for id, file_name, function_name in cur.fetchall():
                                                      ^
SyntaxError: unexpected EOF while parsing
WARNING 2013-07-05 13:27:43,345 base 8697 139681798813440 Not Found: /favicon.ico/
ERROR 2013-07-05 13:37:50,357 base 8868 139970929100544 Internal Server Error: /
Traceback (most recent call last):
  File "/home/imran/Code/splintera-web/venv/local/lib/python2.7/site-packages/django/core/handlers/base.py", line 109, in get_response
    response = middleware_method(request, callback, callback_args, callback_kwargs)
  File "/home/imran/Code/splintera-web/venv/local/lib/python2.7/site-packages/splintera_client/tracer.py", line 24, in process_view
    return trace(view_func)(request, *view_args, **view_kwargs)
  File "/home/imran/Code/splintera-web/venv/local/lib/python2.7/site-packages/splintera_client/tracer.py", line 180, in wrapper
    result = f(*arg, **kw)
  File "/home/imran/Code/splintera-web/splintera/views.py", line 12, in dashboard
    import urllib2
  File "/home/imran/Code/splintera-web/splintera/views.py", line 12, in dashboard
    import urllib2
  File "/home/imran/Code/splintera-web/venv/local/lib/python2.7/site-packages/splintera_client/tracer.py", line 230, in trace_lines
    parsed = ast.parse(source_code)
  File "/usr/lib/python2.7/ast.py", line 37, in parse
    return compile(source, filename, mode, PyCF_ONLY_AST)
TypeError: expected a readable buffer object
WARNING 2013-07-05 13:37:50,776 base 8868 139970929100544 Not Found: /favicon.ico/
WARNING 2013-07-05 13:39:07,628 base 8912 140448575903488 Not Found: /favicon.ico/
ERROR 2013-07-05 14:14:45,204 base 9347 140509125318400 Internal Server Error: /
Traceback (most recent call last):
  File "/home/imran/Code/splintera-web/venv/local/lib/python2.7/site-packages/django/core/handlers/base.py", line 109, in get_response
    response = middleware_method(request, callback, callback_args, callback_kwargs)
  File "/home/imran/Code/splintera-web/venv/local/lib/python2.7/site-packages/splintera_client/tracer.py", line 24, in process_view
    return trace(view_func)(request, *view_args, **view_kwargs)
  File "/home/imran/Code/splintera-web/venv/local/lib/python2.7/site-packages/splintera_client/tracer.py", line 180, in wrapper
    result = f(*arg, **kw)
  File "/home/imran/Code/splintera-web/splintera/views.py", line 12, in dashboard
    import urllib2
  File "/home/imran/Code/splintera-web/splintera/views.py", line 12, in dashboard
    import urllib2
  File "/home/imran/Code/splintera-web/venv/local/lib/python2.7/site-packages/splintera_client/tracer.py", line 241, in trace_lines
    print key + type(key)
TypeError: cannot concatenate 'str' and 'type' objects
WARNING 2013-07-05 14:14:45,579 base 9347 140509125318400 Not Found: /favicon.ico/
ERROR 2013-07-05 14:15:26,512 base 9385 140385751967488 Internal Server Error: /
Traceback (most recent call last):
  File "/home/imran/Code/splintera-web/venv/local/lib/python2.7/site-packages/django/core/handlers/base.py", line 109, in get_response
    response = middleware_method(request, callback, callback_args, callback_kwargs)
  File "/home/imran/Code/splintera-web/venv/local/lib/python2.7/site-packages/splintera_client/tracer.py", line 24, in process_view
    return trace(view_func)(request, *view_args, **view_kwargs)
  File "/home/imran/Code/splintera-web/venv/local/lib/python2.7/site-packages/splintera_client/tracer.py", line 180, in wrapper
    result = f(*arg, **kw)
  File "/home/imran/Code/splintera-web/splintera/views.py", line 12, in dashboard
    import urllib2
  File "/home/imran/Code/splintera-web/splintera/views.py", line 12, in dashboard
    import urllib2
  File "/home/imran/Code/splintera-web/venv/local/lib/python2.7/site-packages/splintera_client/tracer.py", line 241, in trace_lines
    print key + type(key)
TypeError: cannot concatenate 'str' and 'type' objects
WARNING 2013-07-05 14:15:26,890 base 9385 140385751967488 Not Found: /favicon.ico/
WARNING 2013-07-05 14:18:41,422 base 9418 140366121752320 Not Found: /favicon.ico/
WARNING 2013-07-05 14:19:21,634 base 9468 139878707975936 Not Found: /favicon.ico/
ERROR 2013-07-05 14:25:37,774 base 9563 140194107881216 Internal Server Error: /
Traceback (most recent call last):
  File "/home/imran/Code/splintera-web/venv/local/lib/python2.7/site-packages/django/core/handlers/base.py", line 109, in get_response
    response = middleware_method(request, callback, callback_args, callback_kwargs)
  File "/home/imran/Code/splintera-web/venv/local/lib/python2.7/site-packages/splintera_client/tracer.py", line 24, in process_view
    return trace(view_func)(request, *view_args, **view_kwargs)
  File "/home/imran/Code/splintera-web/venv/local/lib/python2.7/site-packages/splintera_client/tracer.py", line 180, in wrapper
    result = f(*arg, **kw)
  File "/home/imran/Code/splintera-web/splintera/views.py", line 12, in dashboard
    import urllib2
  File "/home/imran/Code/splintera-web/splintera/views.py", line 12, in dashboard
    import urllib2
  File "/home/imran/Code/splintera-web/venv/local/lib/python2.7/site-packages/splintera_client/tracer.py", line 240, in trace_lines
    for key,value in frame.f_locals().items():
TypeError: 'dict' object is not callable
WARNING 2013-07-05 14:25:38,200 base 9563 140194107881216 Not Found: /favicon.ico/
WARNING 2013-07-05 14:30:13,078 base 9656 139757256767232 Not Found: /favicon.ico/
WARNING 2013-07-05 14:42:30,097 base 9887 140113834727168 Not Found: /favicon.ico/
WARNING 2013-07-05 15:08:03,123 base 10291 140489614767872 Not Found: /favicon.ico/
WARNING 2013-07-05 15:14:56,082 base 10458 140725646763776 Not Found: /favicon.ico/
ERROR 2013-07-05 16:22:45,947 base 11392 140032882124544 Internal Server Error: /
Traceback (most recent call last):
  File "/home/imran/Code/splintera-web/venv/local/lib/python2.7/site-packages/django/core/handlers/base.py", line 109, in get_response
    response = middleware_method(request, callback, callback_args, callback_kwargs)
  File "/home/imran/Code/splintera-web/venv/local/lib/python2.7/site-packages/splintera_client/tracer.py", line 24, in process_view
    return trace(view_func)(request, *view_args, **view_kwargs)
  File "/home/imran/Code/splintera-web/venv/local/lib/python2.7/site-packages/splintera_client/tracer.py", line 180, in wrapper
    result = f(*arg, **kw)
  File "/home/imran/Code/splintera-web/splintera/views.py", line 12, in dashboard
    import urllib2
  File "/home/imran/Code/splintera-web/splintera/views.py", line 12, in dashboard
    import urllib2
  File "/home/imran/Code/splintera-web/venv/local/lib/python2.7/site-packages/splintera_client/tracer.py", line 242, in trace_lines
    p.visit(node)
NameError: global name 'node' is not defined
WARNING 2013-07-05 16:22:46,331 base 11392 140032882124544 Not Found: /favicon.ico/
WARNING 2013-07-05 16:23:29,940 base 11423 139958138865408 Not Found: /favicon.ico/
ERROR 2013-07-05 16:30:04,303 base 11532 140381555439360 Internal Server Error: /
Traceback (most recent call last):
  File "/home/imran/Code/splintera-web/venv/local/lib/python2.7/site-packages/django/core/handlers/base.py", line 109, in get_response
    response = middleware_method(request, callback, callback_args, callback_kwargs)
  File "/home/imran/Code/splintera-web/venv/local/lib/python2.7/site-packages/splintera_client/tracer.py", line 24, in process_view
    return trace(view_func)(request, *view_args, **view_kwargs)
  File "/home/imran/Code/splintera-web/venv/local/lib/python2.7/site-packages/splintera_client/tracer.py", line 180, in wrapper
    result = f(*arg, **kw)
  File "/home/imran/Code/splintera-web/splintera/views.py", line 12, in dashboard
    import urllib2
  File "/home/imran/Code/splintera-web/splintera/views.py", line 12, in dashboard
    import urllib2
  File "/home/imran/Code/splintera-web/venv/local/lib/python2.7/site-packages/splintera_client/tracer.py", line 242, in trace_lines
    p.visit(parsed)
  File "/usr/lib/python2.7/ast.py", line 241, in visit
    return visitor(node)
  File "/home/imran/Code/splintera-web/venv/local/lib/python2.7/site-packages/splintera_client/tracer.py", line 216, in generic_visit
    ast.NodeVisitor.generic_visit(self, node)
  File "/usr/lib/python2.7/ast.py", line 249, in generic_visit
    self.visit(item)
  File "/usr/lib/python2.7/ast.py", line 241, in visit
    return visitor(node)
  File "/home/imran/Code/splintera-web/venv/local/lib/python2.7/site-packages/splintera_client/tracer.py", line 216, in generic_visit
    ast.NodeVisitor.generic_visit(self, node)
  File "/usr/lib/python2.7/ast.py", line 249, in generic_visit
    self.visit(item)
  File "/usr/lib/python2.7/ast.py", line 241, in visit
    return visitor(node)
  File "/home/imran/Code/splintera-web/venv/local/lib/python2.7/site-packages/splintera_client/tracer.py", line 219, in visit_Assign
    print "Assign :" + node.lineno
TypeError: cannot concatenate 'str' and 'int' objects
WARNING 2013-07-05 16:30:04,738 base 11532 140381555439360 Not Found: /favicon.ico/
WARNING 2013-07-05 16:30:22,063 base 11560 140221615994624 Not Found: /favicon.ico/
ERROR 2013-07-05 16:33:15,435 base 11703 140392826791680 Internal Server Error: /
Traceback (most recent call last):
  File "/home/imran/Code/splintera-web/venv/local/lib/python2.7/site-packages/django/core/handlers/base.py", line 109, in get_response
    response = middleware_method(request, callback, callback_args, callback_kwargs)
  File "/home/imran/Code/splintera-web/venv/local/lib/python2.7/site-packages/splintera_client/tracer.py", line 24, in process_view
    return trace(view_func)(request, *view_args, **view_kwargs)
  File "/home/imran/Code/splintera-web/venv/local/lib/python2.7/site-packages/splintera_client/tracer.py", line 180, in wrapper
    result = f(*arg, **kw)
  File "/home/imran/Code/splintera-web/splintera/views.py", line 12, in dashboard
    import urllib2
  File "/home/imran/Code/splintera-web/splintera/views.py", line 12, in dashboard
    import urllib2
  File "/home/imran/Code/splintera-web/venv/local/lib/python2.7/site-packages/splintera_client/tracer.py", line 244, in trace_lines
    p.visit(parsed)
  File "/usr/lib/python2.7/ast.py", line 241, in visit
    return visitor(node)
  File "/home/imran/Code/splintera-web/venv/local/lib/python2.7/site-packages/splintera_client/tracer.py", line 216, in generic_visit
    ast.NodeVisitor.generic_visit(self, node)
  File "/usr/lib/python2.7/ast.py", line 249, in generic_visit
    self.visit(item)
  File "/usr/lib/python2.7/ast.py", line 241, in visit
    return visitor(node)
  File "/home/imran/Code/splintera-web/venv/local/lib/python2.7/site-packages/splintera_client/tracer.py", line 216, in generic_visit
    ast.NodeVisitor.generic_visit(self, node)
  File "/usr/lib/python2.7/ast.py", line 249, in generic_visit
    self.visit(item)
  File "/usr/lib/python2.7/ast.py", line 241, in visit
    return visitor(node)
  File "/home/imran/Code/splintera-web/venv/local/lib/python2.7/site-packages/splintera_client/tracer.py", line 220, in visit_Assign
    print str(node.nodes)
AttributeError: 'Assign' object has no attribute 'nodes'
WARNING 2013-07-05 16:33:15,844 base 11703 140392826791680 Not Found: /favicon.ico/
WARNING 2013-07-05 16:41:38,659 base 11847 140659145787136 Not Found: /favicon.ico/
WARNING 2013-07-05 16:49:08,519 base 11957 140290052830976 Not Found: /favicon.ico/
WARNING 2013-07-05 16:54:20,383 base 12045 139959061071616 Not Found: /favicon.ico/
WARNING 2013-07-05 16:58:30,710 base 12133 140732153480960 Not Found: /favicon.ico/
ERROR 2013-07-05 17:00:49,013 base 12286 140520699946752 Internal Server Error: /
Traceback (most recent call last):
  File "/home/imran/Code/splintera-web/venv/local/lib/python2.7/site-packages/django/core/handlers/base.py", line 109, in get_response
    response = middleware_method(request, callback, callback_args, callback_kwargs)
  File "/home/imran/Code/splintera-web/venv/local/lib/python2.7/site-packages/splintera_client/tracer.py", line 24, in process_view
    return trace(view_func)(request, *view_args, **view_kwargs)
  File "/home/imran/Code/splintera-web/venv/local/lib/python2.7/site-packages/splintera_client/tracer.py", line 180, in wrapper
    result = f(*arg, **kw)
  File "/home/imran/Code/splintera-web/splintera/views.py", line 12, in dashboard
    import urllib2
  File "/home/imran/Code/splintera-web/splintera/views.py", line 12, in dashboard
    import urllib2
  File "/home/imran/Code/splintera-web/venv/local/lib/python2.7/site-packages/splintera_client/tracer.py", line 253, in trace_lines
    p.visit(parsed)
  File "/usr/lib/python2.7/ast.py", line 241, in visit
    return visitor(node)
  File "/home/imran/Code/splintera-web/venv/local/lib/python2.7/site-packages/splintera_client/tracer.py", line 216, in generic_visit
    ast.NodeVisitor.generic_visit(self, node)
  File "/usr/lib/python2.7/ast.py", line 249, in generic_visit
    self.visit(item)
  File "/usr/lib/python2.7/ast.py", line 241, in visit
    return visitor(node)
  File "/home/imran/Code/splintera-web/venv/local/lib/python2.7/site-packages/splintera_client/tracer.py", line 216, in generic_visit
    ast.NodeVisitor.generic_visit(self, node)
  File "/usr/lib/python2.7/ast.py", line 249, in generic_visit
    self.visit(item)
  File "/usr/lib/python2.7/ast.py", line 241, in visit
    return visitor(node)
  File "/home/imran/Code/splintera-web/venv/local/lib/python2.7/site-packages/splintera_client/tracer.py", line 225, in visit_Assign
    for val in node.value:
TypeError: 'Call' object is not iterable
WARNING 2013-07-05 17:00:49,429 base 12286 140520699946752 Not Found: /favicon.ico/
WARNING 2013-07-05 17:10:05,869 base 12495 140427991123712 Not Found: /favicon.ico/
WARNING 2013-07-05 17:23:17,031 base 12664 139957505324800 Not Found: /favicon.ico/
ERROR 2013-07-05 17:26:06,961 base 12727 140522317072128 Internal Server Error: /
Traceback (most recent call last):
  File "/home/imran/Code/splintera-web/venv/local/lib/python2.7/site-packages/django/core/handlers/base.py", line 109, in get_response
    response = middleware_method(request, callback, callback_args, callback_kwargs)
  File "/home/imran/Code/splintera-web/venv/local/lib/python2.7/site-packages/splintera_client/tracer.py", line 24, in process_view
    return trace(view_func)(request, *view_args, **view_kwargs)
  File "/home/imran/Code/splintera-web/venv/local/lib/python2.7/site-packages/splintera_client/tracer.py", line 180, in wrapper
    result = f(*arg, **kw)
  File "/home/imran/Code/splintera-web/splintera/views.py", line 12, in dashboard
    import urllib2
  File "/home/imran/Code/splintera-web/splintera/views.py", line 12, in dashboard
    import urllib2
  File "/home/imran/Code/splintera-web/venv/local/lib/python2.7/site-packages/splintera_client/tracer.py", line 253, in trace_lines
    p.visit(parsed)
  File "/usr/lib/python2.7/ast.py", line 241, in visit
    return visitor(node)
  File "/home/imran/Code/splintera-web/venv/local/lib/python2.7/site-packages/splintera_client/tracer.py", line 216, in generic_visit
    ast.NodeVisitor.generic_visit(self, node)
  File "/usr/lib/python2.7/ast.py", line 249, in generic_visit
    self.visit(item)
  File "/usr/lib/python2.7/ast.py", line 241, in visit
    return visitor(node)
  File "/home/imran/Code/splintera-web/venv/local/lib/python2.7/site-packages/splintera_client/tracer.py", line 216, in generic_visit
    ast.NodeVisitor.generic_visit(self, node)
  File "/usr/lib/python2.7/ast.py", line 249, in generic_visit
    self.visit(item)
  File "/usr/lib/python2.7/ast.py", line 241, in visit
    return visitor(node)
  File "/home/imran/Code/splintera-web/venv/local/lib/python2.7/site-packages/splintera_client/tracer.py", line 227, in visit_Assign
    print node.value.func.value.id
AttributeError: 'Name' object has no attribute 'value'
WARNING 2013-07-05 17:26:07,404 base 12727 140522317072128 Not Found: /favicon.ico/
ERROR 2013-07-05 17:26:33,703 base 12762 140511505393408 Internal Server Error: /
Traceback (most recent call last):
  File "/home/imran/Code/splintera-web/venv/local/lib/python2.7/site-packages/django/core/handlers/base.py", line 109, in get_response
    response = middleware_method(request, callback, callback_args, callback_kwargs)
  File "/home/imran/Code/splintera-web/venv/local/lib/python2.7/site-packages/splintera_client/tracer.py", line 24, in process_view
    return trace(view_func)(request, *view_args, **view_kwargs)
  File "/home/imran/Code/splintera-web/venv/local/lib/python2.7/site-packages/splintera_client/tracer.py", line 180, in wrapper
    result = f(*arg, **kw)
  File "/home/imran/Code/splintera-web/splintera/views.py", line 12, in dashboard
    import urllib2
  File "/home/imran/Code/splintera-web/splintera/views.py", line 12, in dashboard
    import urllib2
  File "/home/imran/Code/splintera-web/venv/local/lib/python2.7/site-packages/splintera_client/tracer.py", line 253, in trace_lines
    p.visit(parsed)
  File "/usr/lib/python2.7/ast.py", line 241, in visit
    return visitor(node)
  File "/home/imran/Code/splintera-web/venv/local/lib/python2.7/site-packages/splintera_client/tracer.py", line 216, in generic_visit
    ast.NodeVisitor.generic_visit(self, node)
  File "/usr/lib/python2.7/ast.py", line 249, in generic_visit
    self.visit(item)
  File "/usr/lib/python2.7/ast.py", line 241, in visit
    return visitor(node)
  File "/home/imran/Code/splintera-web/venv/local/lib/python2.7/site-packages/splintera_client/tracer.py", line 216, in generic_visit
    ast.NodeVisitor.generic_visit(self, node)
  File "/usr/lib/python2.7/ast.py", line 249, in generic_visit
    self.visit(item)
  File "/usr/lib/python2.7/ast.py", line 241, in visit
    return visitor(node)
  File "/home/imran/Code/splintera-web/venv/local/lib/python2.7/site-packages/splintera_client/tracer.py", line 227, in visit_Assign
    print node.value.func.id
AttributeError: 'Attribute' object has no attribute 'id'
WARNING 2013-07-05 17:26:34,125 base 12762 140511505393408 Not Found: /favicon.ico/
ERROR 2013-07-05 17:35:00,512 base 12951 140651566466816 Internal Server Error: /
Traceback (most recent call last):
  File "/home/imran/Code/splintera-web/venv/local/lib/python2.7/site-packages/django/core/handlers/base.py", line 109, in get_response
    response = middleware_method(request, callback, callback_args, callback_kwargs)
  File "/home/imran/Code/splintera-web/venv/local/lib/python2.7/site-packages/splintera_client/tracer.py", line 24, in process_view
    return trace(view_func)(request, *view_args, **view_kwargs)
  File "/home/imran/Code/splintera-web/venv/local/lib/python2.7/site-packages/splintera_client/tracer.py", line 180, in wrapper
    result = f(*arg, **kw)
  File "/home/imran/Code/splintera-web/splintera/views.py", line 12, in dashboard
    import urllib2
  File "/home/imran/Code/splintera-web/splintera/views.py", line 12, in dashboard
    import urllib2
  File "/home/imran/Code/splintera-web/venv/local/lib/python2.7/site-packages/splintera_client/tracer.py", line 257, in trace_lines
    p.visit(parsed)
  File "/usr/lib/python2.7/ast.py", line 241, in visit
    return visitor(node)
  File "/home/imran/Code/splintera-web/venv/local/lib/python2.7/site-packages/splintera_client/tracer.py", line 216, in generic_visit
    ast.NodeVisitor.generic_visit(self, node)
  File "/usr/lib/python2.7/ast.py", line 249, in generic_visit
    self.visit(item)
  File "/usr/lib/python2.7/ast.py", line 241, in visit
    return visitor(node)
  File "/home/imran/Code/splintera-web/venv/local/lib/python2.7/site-packages/splintera_client/tracer.py", line 216, in generic_visit
    ast.NodeVisitor.generic_visit(self, node)
  File "/usr/lib/python2.7/ast.py", line 249, in generic_visit
    self.visit(item)
  File "/usr/lib/python2.7/ast.py", line 241, in visit
    return visitor(node)
  File "/home/imran/Code/splintera-web/venv/local/lib/python2.7/site-packages/splintera_client/tracer.py", line 235, in visit_Assign
    ast.NodeVisitor.generic_visit(self, node)
  File "/usr/lib/python2.7/ast.py", line 251, in generic_visit
    self.visit(value)
  File "/usr/lib/python2.7/ast.py", line 241, in visit
    return visitor(node)
  File "/home/imran/Code/splintera-web/venv/local/lib/python2.7/site-packages/splintera_client/tracer.py", line 220, in visit_Call
    for c in node.func:
TypeError: 'Attribute' object is not iterable
WARNING 2013-07-05 17:35:00,943 base 12951 140651566466816 Not Found: /favicon.ico/
WARNING 2013-07-05 17:35:42,119 base 12984 140456700598016 Not Found: /favicon.ico/
WARNING 2013-07-05 17:49:10,319 base 13104 140349346658048 Not Found: /favicon.ico/
WARNING 2013-07-06 10:36:38,568 base 22587 140633425848064 Not Found: /favicon.ico/
ERROR 2013-07-06 11:22:08,835 base 22995 140065813665536 Internal Server Error: /
Traceback (most recent call last):
  File "/home/imran/Code/splintera-web/venv/local/lib/python2.7/site-packages/django/core/handlers/base.py", line 109, in get_response
    response = middleware_method(request, callback, callback_args, callback_kwargs)
  File "/home/imran/Code/splintera-web/venv/local/lib/python2.7/site-packages/splintera_client/tracer.py", line 24, in process_view
    return trace(view_func)(request, *view_args, **view_kwargs)
  File "/home/imran/Code/splintera-web/venv/local/lib/python2.7/site-packages/splintera_client/tracer.py", line 180, in wrapper
    result = f(*arg, **kw)
  File "/home/imran/Code/splintera-web/splintera/views.py", line 12, in dashboard
    import urllib2
  File "/home/imran/Code/splintera-web/splintera/views.py", line 12, in dashboard
    import urllib2
  File "/home/imran/Code/splintera-web/venv/local/lib/python2.7/site-packages/splintera_client/tracer.py", line 263, in trace_lines
    p.visit(parsed)
  File "/usr/lib/python2.7/ast.py", line 241, in visit
    return visitor(node)
  File "/home/imran/Code/splintera-web/venv/local/lib/python2.7/site-packages/splintera_client/tracer.py", line 216, in generic_visit
    ast.NodeVisitor.generic_visit(self, node)
  File "/usr/lib/python2.7/ast.py", line 249, in generic_visit
    self.visit(item)
  File "/usr/lib/python2.7/ast.py", line 241, in visit
    return visitor(node)
  File "/home/imran/Code/splintera-web/venv/local/lib/python2.7/site-packages/splintera_client/tracer.py", line 216, in generic_visit
    ast.NodeVisitor.generic_visit(self, node)
  File "/usr/lib/python2.7/ast.py", line 249, in generic_visit
    self.visit(item)
  File "/usr/lib/python2.7/ast.py", line 241, in visit
    return visitor(node)
  File "/home/imran/Code/splintera-web/venv/local/lib/python2.7/site-packages/splintera_client/tracer.py", line 241, in visit_Assign
    ast.NodeVisitor.generic_visit(self, node)
  File "/usr/lib/python2.7/ast.py", line 251, in generic_visit
    self.visit(value)
  File "/usr/lib/python2.7/ast.py", line 241, in visit
    return visitor(node)
  File "/home/imran/Code/splintera-web/venv/local/lib/python2.7/site-packages/splintera_client/tracer.py", line 221, in visit_Call
    print node.func.id + node.func.value
AttributeError: 'Name' object has no attribute 'value'
WARNING 2013-07-06 11:22:09,270 base 22995 140065813665536 Not Found: /favicon.ico/
ERROR 2013-07-06 11:22:52,713 base 23030 139882352944896 Internal Server Error: /
Traceback (most recent call last):
  File "/home/imran/Code/splintera-web/venv/local/lib/python2.7/site-packages/django/core/handlers/base.py", line 109, in get_response
    response = middleware_method(request, callback, callback_args, callback_kwargs)
  File "/home/imran/Code/splintera-web/venv/local/lib/python2.7/site-packages/splintera_client/tracer.py", line 24, in process_view
    return trace(view_func)(request, *view_args, **view_kwargs)
  File "/home/imran/Code/splintera-web/venv/local/lib/python2.7/site-packages/splintera_client/tracer.py", line 180, in wrapper
    result = f(*arg, **kw)
  File "/home/imran/Code/splintera-web/splintera/views.py", line 12, in dashboard
    import urllib2
  File "/home/imran/Code/splintera-web/splintera/views.py", line 12, in dashboard
    import urllib2
  File "/home/imran/Code/splintera-web/venv/local/lib/python2.7/site-packages/splintera_client/tracer.py", line 263, in trace_lines
    p.visit(parsed)
  File "/usr/lib/python2.7/ast.py", line 241, in visit
    return visitor(node)
  File "/home/imran/Code/splintera-web/venv/local/lib/python2.7/site-packages/splintera_client/tracer.py", line 216, in generic_visit
    ast.NodeVisitor.generic_visit(self, node)
  File "/usr/lib/python2.7/ast.py", line 249, in generic_visit
    self.visit(item)
  File "/usr/lib/python2.7/ast.py", line 241, in visit
    return visitor(node)
  File "/home/imran/Code/splintera-web/venv/local/lib/python2.7/site-packages/splintera_client/tracer.py", line 216, in generic_visit
    ast.NodeVisitor.generic_visit(self, node)
  File "/usr/lib/python2.7/ast.py", line 249, in generic_visit
    self.visit(item)
  File "/usr/lib/python2.7/ast.py", line 241, in visit
    return visitor(node)
  File "/home/imran/Code/splintera-web/venv/local/lib/python2.7/site-packages/splintera_client/tracer.py", line 241, in visit_Assign
    ast.NodeVisitor.generic_visit(self, node)
  File "/usr/lib/python2.7/ast.py", line 251, in generic_visit
    self.visit(value)
  File "/usr/lib/python2.7/ast.py", line 241, in visit
    return visitor(node)
  File "/home/imran/Code/splintera-web/venv/local/lib/python2.7/site-packages/splintera_client/tracer.py", line 221, in visit_Call
    print node.func.id + node.func.value
AttributeError: 'Name' object has no attribute 'value'
WARNING 2013-07-06 11:22:53,144 base 23030 139882352944896 Not Found: /favicon.ico/
ERROR 2013-07-06 11:23:05,612 base 23030 139882352944896 Internal Server Error: /
Traceback (most recent call last):
  File "/home/imran/Code/splintera-web/venv/local/lib/python2.7/site-packages/django/core/handlers/base.py", line 109, in get_response
    response = middleware_method(request, callback, callback_args, callback_kwargs)
  File "/home/imran/Code/splintera-web/venv/local/lib/python2.7/site-packages/splintera_client/tracer.py", line 24, in process_view
    return trace(view_func)(request, *view_args, **view_kwargs)
  File "/home/imran/Code/splintera-web/venv/local/lib/python2.7/site-packages/splintera_client/tracer.py", line 180, in wrapper
    result = f(*arg, **kw)
  File "/home/imran/Code/splintera-web/splintera/views.py", line 12, in dashboard
    import urllib2
  File "/home/imran/Code/splintera-web/splintera/views.py", line 12, in dashboard
    import urllib2
  File "/home/imran/Code/splintera-web/venv/local/lib/python2.7/site-packages/splintera_client/tracer.py", line 263, in trace_lines
    p.visit(parsed)
  File "/usr/lib/python2.7/ast.py", line 241, in visit
    return visitor(node)
  File "/home/imran/Code/splintera-web/venv/local/lib/python2.7/site-packages/splintera_client/tracer.py", line 216, in generic_visit
    ast.NodeVisitor.generic_visit(self, node)
  File "/usr/lib/python2.7/ast.py", line 249, in generic_visit
    self.visit(item)
  File "/usr/lib/python2.7/ast.py", line 241, in visit
    return visitor(node)
  File "/home/imran/Code/splintera-web/venv/local/lib/python2.7/site-packages/splintera_client/tracer.py", line 216, in generic_visit
    ast.NodeVisitor.generic_visit(self, node)
  File "/usr/lib/python2.7/ast.py", line 249, in generic_visit
    self.visit(item)
  File "/usr/lib/python2.7/ast.py", line 241, in visit
    return visitor(node)
  File "/home/imran/Code/splintera-web/venv/local/lib/python2.7/site-packages/splintera_client/tracer.py", line 241, in visit_Assign
    ast.NodeVisitor.generic_visit(self, node)
  File "/usr/lib/python2.7/ast.py", line 251, in generic_visit
    self.visit(value)
  File "/usr/lib/python2.7/ast.py", line 241, in visit
    return visitor(node)
  File "/home/imran/Code/splintera-web/venv/local/lib/python2.7/site-packages/splintera_client/tracer.py", line 221, in visit_Call
    print node.func.id + node.func.value
AttributeError: 'Name' object has no attribute 'value'
WARNING 2013-07-06 11:23:06,009 base 23030 139882352944896 Not Found: /favicon.ico/
WARNING 2013-07-06 11:23:34,081 base 23074 139942959318784 Not Found: /favicon.ico/
WARNING 2013-07-06 11:29:19,152 base 23156 140512690898688 Not Found: /favicon.ico/
WARNING 2013-07-06 11:36:04,041 base 23222 139690655033088 Not Found: /favicon.ico/
WARNING 2013-07-06 11:41:17,673 base 23317 139904161261312 Not Found: /favicon.ico/
WARNING 2013-07-06 11:42:22,994 base 23377 140443196151552 Not Found: /favicon.ico/
WARNING 2013-07-06 11:50:08,528 base 23440 139962899674880 Not Found: /favicon.ico/
WARNING 2013-07-06 11:51:43,151 base 23511 140191939983104 Not Found: /favicon.ico/
WARNING 2013-07-06 11:52:31,722 base 23552 140042634385152 Not Found: /favicon.ico/
WARNING 2013-07-06 11:53:08,320 base 23581 140258843350784 Not Found: /favicon.ico/
WARNING 2013-07-06 12:03:09,595 base 23763 140355701757696 Not Found: /favicon.ico/
WARNING 2013-07-06 12:03:57,153 base 23802 140309961524992 Not Found: /favicon.ico/
WARNING 2013-07-06 12:13:15,564 base 23874 140060420503296 Not Found: /favicon.ico/
WARNING 2013-07-06 12:23:20,231 base 23952 139781624563456 Not Found: /favicon.ico/
WARNING 2013-07-06 12:28:58,329 base 24025 139734441654016 Not Found: /favicon.ico/
WARNING 2013-07-06 12:30:13,440 base 24058 140616826615552 Not Found: /favicon.ico/
WARNING 2013-07-06 12:41:35,334 base 24469 140275643000576 Not Found: /favicon.ico/
WARNING 2013-07-06 12:42:38,819 base 24517 140396720260864 Not Found: /favicon.ico/
WARNING 2013-07-06 12:43:49,269 base 24572 140348187682560 Not Found: /favicon.ico/
WARNING 2013-07-06 12:46:01,446 base 24651 139648259962624 Not Found: /favicon.ico/
ERROR 2013-07-06 12:57:03,844 base 25053 140469909395200 Internal Server Error: /
Traceback (most recent call last):
  File "/home/imran/Code/splintera-web/venv/local/lib/python2.7/site-packages/django/core/handlers/base.py", line 109, in get_response
    response = middleware_method(request, callback, callback_args, callback_kwargs)
  File "/home/imran/Code/splintera-web/venv/local/lib/python2.7/site-packages/splintera_client/tracer.py", line 24, in process_view
    return trace(view_func)(request, *view_args, **view_kwargs)
  File "/home/imran/Code/splintera-web/venv/local/lib/python2.7/site-packages/splintera_client/tracer.py", line 180, in wrapper
    result = f(*arg, **kw)
  File "/home/imran/Code/splintera-web/splintera/views.py", line 12, in dashboard
    import urllib2
  File "/home/imran/Code/splintera-web/splintera/views.py", line 12, in dashboard
    import urllib2
  File "/home/imran/Code/splintera-web/venv/local/lib/python2.7/site-packages/splintera_client/tracer.py", line 294, in trace_lines
    p.visit(parsed)
  File "/usr/lib/python2.7/ast.py", line 241, in visit
    return visitor(node)
  File "/home/imran/Code/splintera-web/venv/local/lib/python2.7/site-packages/splintera_client/tracer.py", line 223, in generic_visit
    ast.NodeVisitor.generic_visit(self, node)
  File "/usr/lib/python2.7/ast.py", line 249, in generic_visit
    self.visit(item)
  File "/usr/lib/python2.7/ast.py", line 241, in visit
    return visitor(node)
  File "/home/imran/Code/splintera-web/venv/local/lib/python2.7/site-packages/splintera_client/tracer.py", line 223, in generic_visit
    ast.NodeVisitor.generic_visit(self, node)
  File "/usr/lib/python2.7/ast.py", line 251, in generic_visit
    self.visit(value)
  File "/usr/lib/python2.7/ast.py", line 241, in visit
    return visitor(node)
  File "/home/imran/Code/splintera-web/venv/local/lib/python2.7/site-packages/splintera_client/tracer.py", line 223, in generic_visit
    ast.NodeVisitor.generic_visit(self, node)
  File "/usr/lib/python2.7/ast.py", line 249, in generic_visit
    self.visit(item)
  File "/usr/lib/python2.7/ast.py", line 241, in visit
    return visitor(node)
  File "/home/imran/Code/splintera-web/venv/local/lib/python2.7/site-packages/splintera_client/tracer.py", line 252, in visit_Name
    store['LHS'].append(node.id)
TypeError: list indices must be integers, not str
WARNING 2013-07-06 12:57:04,273 base 25053 140469909395200 Not Found: /favicon.ico/
ERROR 2013-07-06 12:58:23,980 base 25178 140017784858368 Internal Server Error: /
Traceback (most recent call last):
  File "/home/imran/Code/splintera-web/venv/local/lib/python2.7/site-packages/django/core/handlers/base.py", line 109, in get_response
    response = middleware_method(request, callback, callback_args, callback_kwargs)
  File "/home/imran/Code/splintera-web/venv/local/lib/python2.7/site-packages/splintera_client/tracer.py", line 24, in process_view
    return trace(view_func)(request, *view_args, **view_kwargs)
  File "/home/imran/Code/splintera-web/venv/local/lib/python2.7/site-packages/splintera_client/tracer.py", line 180, in wrapper
    result = f(*arg, **kw)
  File "/home/imran/Code/splintera-web/splintera/views.py", line 12, in dashboard
    import urllib2
  File "/home/imran/Code/splintera-web/splintera/views.py", line 12, in dashboard
    import urllib2
  File "/home/imran/Code/splintera-web/venv/local/lib/python2.7/site-packages/splintera_client/tracer.py", line 294, in trace_lines
    p.visit(parsed)
  File "/usr/lib/python2.7/ast.py", line 241, in visit
    return visitor(node)
  File "/home/imran/Code/splintera-web/venv/local/lib/python2.7/site-packages/splintera_client/tracer.py", line 223, in generic_visit
    ast.NodeVisitor.generic_visit(self, node)
  File "/usr/lib/python2.7/ast.py", line 249, in generic_visit
    self.visit(item)
  File "/usr/lib/python2.7/ast.py", line 241, in visit
    return visitor(node)
  File "/home/imran/Code/splintera-web/venv/local/lib/python2.7/site-packages/splintera_client/tracer.py", line 223, in generic_visit
    ast.NodeVisitor.generic_visit(self, node)
  File "/usr/lib/python2.7/ast.py", line 251, in generic_visit
    self.visit(value)
  File "/usr/lib/python2.7/ast.py", line 241, in visit
    return visitor(node)
  File "/home/imran/Code/splintera-web/venv/local/lib/python2.7/site-packages/splintera_client/tracer.py", line 223, in generic_visit
    ast.NodeVisitor.generic_visit(self, node)
  File "/usr/lib/python2.7/ast.py", line 249, in generic_visit
    self.visit(item)
  File "/usr/lib/python2.7/ast.py", line 241, in visit
    return visitor(node)
  File "/home/imran/Code/splintera-web/venv/local/lib/python2.7/site-packages/splintera_client/tracer.py", line 252, in visit_Name
    store[0].append(node.id)
AttributeError: 'dict' object has no attribute 'append'
WARNING 2013-07-06 12:58:24,407 base 25178 140017784858368 Not Found: /favicon.ico/
WARNING 2013-07-06 13:02:30,491 base 25363 139858256824064 Not Found: /favicon.ico/
WARNING 2013-07-06 13:07:17,805 base 25628 139722990548736 Not Found: /favicon.ico/
WARNING 2013-07-06 13:10:50,800 base 25752 140127698151168 Not Found: /favicon.ico/
WARNING 2013-07-06 13:17:22,237 base 25868 140452098553600 Not Found: /favicon.ico/
WARNING 2013-07-06 13:18:45,337 base 25933 139729209714432 Not Found: /favicon.ico/
ERROR 2013-07-06 13:42:44,912 base 26602 140394658100992 Internal Server Error: /
Traceback (most recent call last):
  File "/home/imran/Code/splintera-web/venv/local/lib/python2.7/site-packages/django/core/handlers/base.py", line 109, in get_response
    response = middleware_method(request, callback, callback_args, callback_kwargs)
  File "/home/imran/Code/splintera-web/venv/local/lib/python2.7/site-packages/splintera_client/tracer.py", line 25, in process_view
    return trace(view_func)(request, *view_args, **view_kwargs)
  File "/home/imran/Code/splintera-web/venv/local/lib/python2.7/site-packages/splintera_client/tracer.py", line 181, in wrapper
    result = f(*arg, **kw)
  File "/home/imran/Code/splintera-web/splintera/views.py", line 12, in dashboard
    import urllib2
  File "/home/imran/Code/splintera-web/splintera/views.py", line 12, in dashboard
    import urllib2
  File "/home/imran/Code/splintera-web/venv/local/lib/python2.7/site-packages/splintera_client/tracer.py", line 294, in trace_lines
    p.visit(parsed)
  File "/usr/lib/python2.7/ast.py", line 241, in visit
    return visitor(node)
  File "/home/imran/Code/splintera-web/venv/local/lib/python2.7/site-packages/splintera_client/tracer.py", line 224, in generic_visit
    ast.NodeVisitor.generic_visit(self, node)
  File "/usr/lib/python2.7/ast.py", line 249, in generic_visit
    self.visit(item)
  File "/usr/lib/python2.7/ast.py", line 241, in visit
    return visitor(node)
  File "/home/imran/Code/splintera-web/venv/local/lib/python2.7/site-packages/splintera_client/tracer.py", line 224, in generic_visit
    ast.NodeVisitor.generic_visit(self, node)
  File "/usr/lib/python2.7/ast.py", line 249, in generic_visit
    self.visit(item)
  File "/usr/lib/python2.7/ast.py", line 241, in visit
    return visitor(node)
  File "/home/imran/Code/splintera-web/venv/local/lib/python2.7/site-packages/splintera_client/tracer.py", line 272, in visit_Assign
    ast.NodeVisitor.generic_visit(self, node)
  File "/usr/lib/python2.7/ast.py", line 251, in generic_visit
    self.visit(value)
  File "/usr/lib/python2.7/ast.py", line 241, in visit
    return visitor(node)
  File "/home/imran/Code/splintera-web/venv/local/lib/python2.7/site-packages/splintera_client/tracer.py", line 233, in visit_Call
    ast.NodeVisitor.generic_visit(self, node)
  File "/usr/lib/python2.7/ast.py", line 251, in generic_visit
    self.visit(value)
  File "/usr/lib/python2.7/ast.py", line 241, in visit
    return visitor(node)
  File "/home/imran/Code/splintera-web/venv/local/lib/python2.7/site-packages/splintera_client/tracer.py", line 240, in visit_Attribute
    store['RHS_positions'].append([node.id,node.col_offset])
AttributeError: 'Attribute' object has no attribute 'id'
WARNING 2013-07-06 13:42:45,343 base 26602 140394658100992 Not Found: /favicon.ico/
ERROR 2013-07-06 13:43:18,576 base 26636 140360618669824 Internal Server Error: /
Traceback (most recent call last):
  File "/home/imran/Code/splintera-web/venv/local/lib/python2.7/site-packages/django/core/handlers/base.py", line 109, in get_response
    response = middleware_method(request, callback, callback_args, callback_kwargs)
  File "/home/imran/Code/splintera-web/venv/local/lib/python2.7/site-packages/splintera_client/tracer.py", line 25, in process_view
    return trace(view_func)(request, *view_args, **view_kwargs)
  File "/home/imran/Code/splintera-web/venv/local/lib/python2.7/site-packages/splintera_client/tracer.py", line 181, in wrapper
    result = f(*arg, **kw)
  File "/home/imran/Code/splintera-web/splintera/views.py", line 12, in dashboard
    import urllib2
  File "/home/imran/Code/splintera-web/splintera/views.py", line 12, in dashboard
    import urllib2
  File "/home/imran/Code/splintera-web/venv/local/lib/python2.7/site-packages/splintera_client/tracer.py", line 295, in trace_lines
    p.print_tokens()
  File "/home/imran/Code/splintera-web/venv/local/lib/python2.7/site-packages/splintera_client/tracer.py", line 220, in print_tokens
    print self._per_line_tokens['LHS'] + self._per_line_tokens['RHS']
KeyError: 'LHS'
WARNING 2013-07-06 13:43:18,968 base 26636 140360618669824 Not Found: /favicon.ico/
ERROR 2013-07-06 13:45:19,066 base 26775 139978075657984 Internal Server Error: /
Traceback (most recent call last):
  File "/home/imran/Code/splintera-web/venv/local/lib/python2.7/site-packages/django/core/handlers/base.py", line 109, in get_response
    response = middleware_method(request, callback, callback_args, callback_kwargs)
  File "/home/imran/Code/splintera-web/venv/local/lib/python2.7/site-packages/splintera_client/tracer.py", line 25, in process_view
    return trace(view_func)(request, *view_args, **view_kwargs)
  File "/home/imran/Code/splintera-web/venv/local/lib/python2.7/site-packages/splintera_client/tracer.py", line 181, in wrapper
    result = f(*arg, **kw)
  File "/home/imran/Code/splintera-web/splintera/views.py", line 12, in dashboard
    import urllib2
  File "/home/imran/Code/splintera-web/splintera/views.py", line 12, in dashboard
    import urllib2
  File "/home/imran/Code/splintera-web/venv/local/lib/python2.7/site-packages/splintera_client/tracer.py", line 296, in trace_lines
    p.print_tokens()
  File "/home/imran/Code/splintera-web/venv/local/lib/python2.7/site-packages/splintera_client/tracer.py", line 220, in print_tokens
    for key,val in self._per_line_tokens:
TypeError: 'int' object is not iterable
WARNING 2013-07-06 13:45:19,450 base 26775 139978075657984 Not Found: /favicon.ico/
ERROR 2013-07-06 13:47:45,653 base 26926 139760274372352 Internal Server Error: /
Traceback (most recent call last):
  File "/home/imran/Code/splintera-web/venv/local/lib/python2.7/site-packages/django/core/handlers/base.py", line 109, in get_response
    response = middleware_method(request, callback, callback_args, callback_kwargs)
  File "/home/imran/Code/splintera-web/venv/local/lib/python2.7/site-packages/splintera_client/tracer.py", line 25, in process_view
    return trace(view_func)(request, *view_args, **view_kwargs)
  File "/home/imran/Code/splintera-web/venv/local/lib/python2.7/site-packages/splintera_client/tracer.py", line 181, in wrapper
    result = f(*arg, **kw)
  File "/home/imran/Code/splintera-web/splintera/views.py", line 12, in dashboard
    import urllib2
  File "/home/imran/Code/splintera-web/splintera/views.py", line 12, in dashboard
    import urllib2
  File "/home/imran/Code/splintera-web/venv/local/lib/python2.7/site-packages/splintera_client/tracer.py", line 296, in trace_lines
    p.print_tokens()
  File "/home/imran/Code/splintera-web/venv/local/lib/python2.7/site-packages/splintera_client/tracer.py", line 221, in print_tokens
    print key + ': LHS ' + val['LHS'] + 'RHS: ' + val['RHS']
TypeError: unsupported operand type(s) for +: 'int' and 'str'
WARNING 2013-07-06 13:47:46,059 base 26926 139760274372352 Not Found: /favicon.ico/
ERROR 2013-07-06 13:48:01,575 base 26954 140147762255616 Internal Server Error: /
Traceback (most recent call last):
  File "/home/imran/Code/splintera-web/venv/local/lib/python2.7/site-packages/django/core/handlers/base.py", line 109, in get_response
    response = middleware_method(request, callback, callback_args, callback_kwargs)
  File "/home/imran/Code/splintera-web/venv/local/lib/python2.7/site-packages/splintera_client/tracer.py", line 25, in process_view
    return trace(view_func)(request, *view_args, **view_kwargs)
  File "/home/imran/Code/splintera-web/venv/local/lib/python2.7/site-packages/splintera_client/tracer.py", line 181, in wrapper
    result = f(*arg, **kw)
  File "/home/imran/Code/splintera-web/splintera/views.py", line 12, in dashboard
    import urllib2
  File "/home/imran/Code/splintera-web/splintera/views.py", line 12, in dashboard
    import urllib2
  File "/home/imran/Code/splintera-web/venv/local/lib/python2.7/site-packages/splintera_client/tracer.py", line 296, in trace_lines
    p.print_tokens()
  File "/home/imran/Code/splintera-web/venv/local/lib/python2.7/site-packages/splintera_client/tracer.py", line 221, in print_tokens
    print str(key) + ': LHS ' + val['LHS'] + 'RHS: ' + val['RHS']
TypeError: cannot concatenate 'str' and 'list' objects
WARNING 2013-07-06 13:48:01,906 base 26954 140147762255616 Not Found: /favicon.ico/
WARNING 2013-07-06 13:48:24,948 base 26993 139947746973440 Not Found: /favicon.ico/
WARNING 2013-07-06 16:02:43,428 base 29682 140330464302848 Not Found: /favicon.ico/
WARNING 2013-07-06 16:12:21,532 base 29839 140662555121408 Not Found: /favicon.ico/
WARNING 2013-07-06 18:16:30,114 base 30385 140353484912384 Not Found: /favicon.ico/
WARNING 2013-07-06 18:17:47,139 base 30431 140660648703744 Not Found: /favicon.ico/
